try {
    // const num = 2
    // num = 5
    //the above errors are not caught
    throw("Lol")
} catch(error1) {
    console.log(error1)
}

throw("oasin")